Workbook

Sheet 表紙
B3: 株式会社HAL名古屋 | M3: 御中 | AF3: システム名
I16: 画 面 設 計 書
AF45: 管理番号 | AL45: 20230711NHIH22000X001
AF47: 改定日 | AL47: 46206
AF49: 改訂者 | AL49: 山田 太郎

Sheet 改訂履歴
A1: 改訂履歴
A4: 項番 | C4: 改訂日 | G4: 改訂者 | K4: 対象 | U4: 改訂内容
A5: =ROW()-4 -> 1 | K5: 全ページ | U5: 初版作成
A6: =ROW()-4 -> 2
A7: =ROW()-4 -> 3
A8: =ROW()-4 -> 4
A9: =ROW()-4 -> 5
A10: =ROW()-4 -> 6
A11: =ROW()-4 -> 7
A12: =ROW()-4 -> 8
A13: =ROW()-4 -> 9
A14: =ROW()-4 -> 10
A15: =ROW()-4 -> 11
A16: =ROW()-4 -> 12
A17: =ROW()-4 -> 13
... A46: =ROW()-4 -> 42

Sheet 画面一覧
A1: 画面設計書 | T1: システムID | X1: =[1]表紙!AL45 -> 20230711NHIH22000X001 | AH1: 改訂日 | AL1: 45106 | AU1: No. | AW1: 1
T2: システム名称 | X2: =[1]表紙!AL3 -> 0 | AH2: 改訂者 | AL2: HAL太郎
A4: 画面一覧
A6: No. | C6: 画面名称 | Z6: 概要
A7: 1 | C7: トップページ | Z7: ログイン、新規登録への遷移
A8: 2 | C8: 新規登録 | Z8: ユーザーの新規登録
A9: 3 | C9: 本人確認 | Z9: 本人確認書類の認証による信頼性担保機能
A10: 4 | C10: ログイン | Z10: 会員のログイン/ログアウト
A11: 5 | C11: ホーム | Z11: ホーム画面
A12: 6 | C12: プロフィール | Z12: プロフィール画面
A13: 7 | C13: 会員情報編集 | Z13: 会員情報の確認/編集
A14: 8 | C14: ユーザー設定 | Z14: ユーザーの履歴からおすすめとして表示するものを判断する
A15: 9 | C15: 出品機能 | Z15: 商品の出品（商品名、値段設定など）[タイトル、説明文、カテゴリ、 価格等の入力／1商品につき複数枚の画像をアップロード （画像スライダー用）／出品中、取引中、売却済みの状態管理と編集・削除]
A16: 10 | C16: 出品一覧 | Z16: 出品した商品を一覧で表示する画面
A17: 11 | C17: 出品内容編集 | Z17: 出品した商品の詳細情報などを後から編集する画面
A18: 12 | C18: 出品取り下げ | Z18: 出品した商品を取り下げる
... A30: 24 | C30: 自身の出品一覧 | Z30: 自分が出品した商品の一覧表示
A31: 25
A32: 26
A33: 27
A34: 28
A35: 29
A36: 30
A37: 31
A38: 32
A39: 33
A40: 34
A41: 35
A42: 36
... A47: 41

Sheet 画面設計書(サンプル画面)
A1: 機能設計書 | AI1: システム名 | AU1: サブシステム名 | BG1: 機能名 | CQ1: 作成日 | CX1: 作成者 | DG1: 更新日 | DN1: 更新者
AI2: 統一WMS | AU2: 列マスタ | BG2: 列マスタ | CQ2: 44756 | CX2: 〇〇 〇〇 | DG2: 44762 | DN2: 〇〇 〇〇
B5: 【画面イメージ】 | CD5: 【機能概要】
CE6: ・ | CF6: 列マスタテーブルのマスタメンテナンスを行う昨日
B7: ダイソーWMS
B8: 戻る | F8: 列 一覧
K11: エリアコード： | V11: ▼ | AG11: 列グループコード： | AR11: ▼ | AZ11: 列コード：
CD12: 【画面概要】
K13: 左右区分： | V13: ▼ | BT13: 検索 | CE13: ・ | CF13: 列の条件設定および検索
CE14: ・ | CF14: 各列の詳細情報への遷移
C16: No. | F16: エリア | J16: 列グループ | P16: 列 | T16: 列名称 | AF16: 列区分 | AK16: 左右区分 | AQ16: 登録日時 | BB16: 登録ユーザー | BI16: 更新日時 | BT16: 更新ユーザー | CD16: 【ボタン】
C17: 1 | F17: 1Z | J17: AA | P17: A1 | T17: 列1 | AF17: 1 | AK17: 左 | AQ17: 2022/07/03 12:34:56 | BB17: 大創 太郎 | BI17: 2022/07/03 12:34:56 | BT17: 大創 太郎 | CF17: 項目 | CK17: 概要
C18: 2 | F18: 1Z | J18: AA | P18: A2 | T18: 列2 | AF18: 1 | AK18: 右 | AQ18: 2022/07/03 12:34:56 | BB18: 大創 太郎 | BI18: 2022/07/03 12:34:56 | BT18: 大創 太郎 | CF18: 戻る | CK18: 起動元画面へ戻る。
CF20: 検索 | CK20: 項目入力部の内容を検索条件として、
CK21: データを検索し一覧に表示する。
CF22: 新規登録 | CK22: 列 新規登録画面へ遷移する。
CF24: 更新 | CK24: 列 編集画面へ遷移する。
CF26: 削除 | CK26: 選択しているレコードを削除する。
CD29: 【権限仕様】
CD33: 【備考】
CF35: 削除条件
CF36: ・ | CG36: 削除対象の列に属するロケーションマスタが存在している場合、削除は出来ない事とする
BG37: 新規登録 | BN37: 更新 | BU37: 削除 | CG37: ※列マスタの削除は紐づくロケーションマスタをすべて削除した状態でのみ可能とする
B42: 【画面項目定義】
A44: No | C44: 画面項目名 | O44: ラベル名 | V44: 項目ID | AE44: 取得テーブル | AN44: 上位 | AQ44: 種別 | AX44: 表示仕様 | BG44: 必須 | BO44: 型 | BS44: 桁 | BV44: 入力制限 | CC44: 入力制限備考 | CT44: 備考
A45: ↓ヘッダー
A46: 1 | C46: エリアコード | O46: エリアコード | V46: cmbAreaCode | AE46: - | AQ46: コンボボックス | AX46: 活性 | BO46: 文字列 | BS46: 4
A47: 2 | C47: 列グループコード | O47: 列グループコード | V47: cmbBankGroupCode | AE47: - | AQ47: コンボボックス | AX47: 活性 | BO47: 文字列 | BS47: 5 | CC47: 検索条件欄のエリアコードに紐づく列グループの一覧をコンボボックスで選択可能とする
A48: 3 | C48: 列コード | O48: 列コード | V48: txtBankCode | AE48: - | AQ48: テキストエリア | AX48: 活性 | BO48: 文字列 | BS48: 5 | CC48: 曖昧検索可(前方、後方両方)
A49: 4 | C49: 左右区分 | O49: 左右区分 | V49: cmbLRKbn | AE49: - | AQ49: コンボボックス | AX49: 活性 | BO49: 文字列 | BS49: 1
A50: 5 | C50: エラーメッセージ | O50: エラーメッセージ | V50: txtMessage | AE50: - | AQ50: テキストエリア | AX50: 非活性 | BO50: 文字列
A51: ↓一覧
A52: 6 | C52: No. | O52: No. | V52: RowNumber | AE52: - | AQ52: ラベル | AX52: 非活性 | BO52: 文字列 | BS52: -
A53: 7 | C53: ロケエリアコード | O53: エリア | V53: AreaCd | AE53: TBL_WMS.MstBank | AQ53: ラベル | AX53: 非活性 | BO53: 文字列 | BS53: 4
A54: 8 | C54: 列グループコード | O54: 列グループ | V54: BankGroupCd | AE54: TBL_WMS.MstBank | AQ54: ラベル | AX54: 非活性 | BO54: 文字列 | BS54: 5
A55: 9 | C55: 列コード | O55: 列 | V55: BankCd | AE55: TBL_WMS.MstBank | AQ55: ラベル | AX55: 非活性 | BO55: 文字列 | BS55: 5
A56: 10 | C56: 列名称 | O56: 列名称 | V56: BankName | AE56: TBL_WMS.MstBank | AQ56: ラベル | AX56: 非活性 | BO56: 文字列 | BS56: 40
A57: 11 | C57: 列区分 | O57: 列区分 | V57: BankKbn | AE57: TBL_WMS.MstBank | AQ57: ラベル | AX57: 非活性 | BO57: 文字列 | BS57: 2
A58: 12 | C58: 左右区分 | O58: 左右区分 | V58: LRKbn | AE58: TBL_WMS.MstBank | AQ58: ラベル | AX58: 非活性 | BO58: 文字列 | BS58: 1
A59: 13 | C59: 登録日時 | O59: 登録日時 | V59: AddDatetime | AE59: TBL_WMS.MstBank | AQ59: ラベル | AX59: 非活性 | BO59: 文字列 | BS59: 19
...

Sheet 画面設計書(購入手続き画面) 
A1: 画面設計書 | T1: システムID | X1: =表紙!AL45&"-0"&'画面設計書(購入手続き画面) '!AW1 -> 20230711NHIH22000X001-016 | AH1: 改訂日 | AL1: 46206 | AU1: No. | AW1: 16
T2: システム名称 | X2: =表紙!AL3 -> 0 | AH2: 改訂者 | AL2: HAL太郎
A5: 画面設計書-画面名
A44: No | C44: 画面項目名 | O44: ラベル名 | V44: 項目ID | AE44: 取得テーブル | AN44: 上位 | AQ44: 種別 | AX44: 表示仕様 | BG44: 必須 | BO44: 型 | BS44: 桁 | BV44: 入力制限 | CC44: 入力制限備考 | CT44: 備考
A45: ↓header
A46: 1 | C46: 戻る | O46: 戻る | V46: Return | AE46: - | AQ46: 種別 | AX46: 活性 | CT46: 前の画面に戻る
A47: ↓main
A48: 2 | C48: 登録済み住所 | O48: 登録済み住所 | V48: Registered address | AE48: m_member | AQ48: ラジオ | AX48: 活性 | BO48: 整数 | CT48: 登録済み住所を使用する場合選択
A49: 3 | C49: 新しい住所 | O49: 新しい住所 | V49: New address | AE49: m_member | AQ49: ラジオ | AX49: 活性 | BO49: 整数 | CT49: 新しい住所を登録する場合選択
A50: 4 | C50: 登録済み住所使用リスト | O50: 登録住所 | V50: addressList | AE50: m_member | AQ50: プルダウン | AX50: 活性 | BO50: 文字列 | CT50: 登録済み住所を表示
A51: 5 | C51: 新しい住所入力 | O51: 住所入力 | V51: New address input | AE51: m_member | AQ51: テキスト | AX51: 活性 | BO51: 文字列 | BU51: 225 | CT51: 新しい配送先住所を登録してもらう
A52: 6 | C52: お名前 | O52: お名前 | V52: name | AE52: m_member | AQ52: テキスト | AX52: 活性 | BO52: 文字列 | BS52: 20 | CT52: 名前を表示
A53: 7 | C53: メールアドレス | O53: メールアドレス | V53: Email | AE53: m_member | AQ53: テキスト | AX53: 活性 | BO53: 文字列 | BU53: 20 | CT53: メールアドレスを表示
A54: 8 | C54: 郵便番号 | O54: 郵便番号 | V54: postalCode | AE54: m_member | AQ54: テキスト | AX54: 活性 | BO54: 文字列 | BU54: 7 | BV54: 数字のみ | CC54: ハイフン可 | CT54: 郵便番号表示
A55: 9 | C55: 都道府県 | O55: 都道府県 | V55: prefecture | AE55: m_member | AQ55: プルダウン | AX55: 活性 | BO55: 文字列 | CT55: 都道府県表示
A56: 10 | C56: 市区町村・番地 | O56: 市区町村・番地 | V56: addressList | AE56: m_member | AQ56: テキスト | AX56: 活性 | BO56: 文字列 | BS56: 225 | CT56: 市区町村・番地を表示
A57: 11 | C57: 建物名・部屋番号（任意） | O57: 建物名・部屋番号 | V57: aptRoom | AE57: m_member | AQ57: テキスト | AX57: 活性 | BO57: 文字列 | BS57: 50 | CT57: 建物名・部屋番号を表示
A58: 12 | C58: 電話番号 | O58: 電話番号 | V58: telNumber | AE58: m_member | AQ58: テキスト | AX58: 活性 | BO58: 文字列 | BS58: 20 | BV58: 数字のみ | CC58: ハイフン可 | CT58: 電話番号を表示
A59: 13 | C59: 銀行振込 | O59: 銀行振込 | V59: Bank transfer | AE59: - | AQ59: ラジオ | AX59: 活性 | BO59: 整数 | CT59: 銀行振込の場合選択
A60: 14 | C60: コンビニ支払い | O60: コンビニ支払い | V60: Convenience store payment | AE60: - | AQ60: ラジオ | AX60: 活性 | BO60: 整数 | CT60: コンビニ支払いの場合選択
A61: 15 | C61: クレジット支払い | O61: クレジット支払い | V61: Credit payment | AE61: - | AQ61: ラジオ | AX61: 活性 | BO61: 整数 | CT61: クレジット支払いの場合選択
A62: 16 | C62: カード番号 | O62: カード番号 | V62: cardNumber | AE62: - | AQ62: テキスト | AX62: 活性 | BO62: 数値 | BV62: 数字のみ | CT62: カード番号の入力欄
A63: 17 | C63: 有効期限 | O63: 有効期限 | V63: cardExpire | AE63: - | AQ63: テキスト | AX63: 活性 | BO63: 文字列 | BS63: 19 | BV63: 数字＋記号 | CC63: スラッシュ可 | CT63: 有効期限の入力欄
A64: 18 | C64: 名義人 | O64: 名義人 | V64: cardHolder | AE64: - | AQ64: テキスト | AX64: 活性 | BO64: 文字列 | BU64: 20 | BV64: 数字のみ | CT64: 名義人の入力欄
A65: 19 | C65: セキュリティコード | O65: セキュリティコード | V65: cardCvv | AE65: - | AQ65: テキスト | AX65: 活性 | BO65: 整数 | BS65: 4 | CT65: セキュリティコードの入力
A66: 20 | C66: メルカリ便 | O66: メルカリ便 | V66: merukaribin | AE66: - | AQ66: ラジオ | AX66: 活性 | BO66: 数値 | CT66: メルカリ便の場合選択
A67: 21 | C67: ゆうパック | O67: ゆうパック | V67: yuupakku | AE67: - | AQ67: ラジオ | AX67: 活性 | BO67: 数値 | CT67: ゆうパックの場合選択
A68: 22 | C68: 商品画像 | O68: 商品画像 | V68: ProductImage | AE68: m_Image | AQ68: 画像 | AX68: 活性 | BO68: 数値 | CT68: 商品画像を表示
A69: 23 | C69: 商品名 | O69: 商品名 | V69: ProductName | AE69: m_Secondhand clothes | AQ69: ラベル | AX69: 活性 | BO69: 文字列 | BS69: 20 | CT69: 商品名を表示
A70: 24 | C70: カラー | O70: カラー | V70: Color | AE70: m_Color info | AQ70: ラベル | AX70: 活性 | BO70: 文字列 | BU70: 20 | CT70: 商品のカラーを表示
A71: 25 | C71: サイズ | O71: サイズ | V71: size | AE71: m_size | AQ71: ラベル | AX71: 活性 | BO71: 文字列 | BU71: 20 | CT71: 商品のサイズを表示
A72: 26 | C72: 出品者名 | O72: 出品者名 | V72: Seller Name | AE72: m_member | AQ72: ラベル | AX72: 活性 | BO72: 文字列 | BU72: 20 | CT72: 商品を出品した会員名を表示
A73: 27 | C73: 価格 | O73: 商品価格 | V73: Price | AE73: m_Secondhand clothes | AQ73: ラベル | AX73: 活性 | BO73: 文字列 | BS73: 5 | CT73: 商品の価格を表示
A74: 28 | C74: 数量 | O74: 数量 | V74: ProductQty | AE74: t_cart | AQ74: ラベル | AX74: 活性 | BO74: 数値 | CT74: 注文商品の数量
A75: 29 | C75: 小計 | O75: 小計 | V75: subtotal | AE75: - | AQ75: ラベル | AX75: 活性 | BO75: 整数 | CT75: 各商品の小計を表示
A76: 30 | C76: 送料 | O76: 送料 | V76: shippingFee | AE76: - | AQ76: ラベル | AX76: 活性 | BO76: 数値 | CT76: 配送料を表示
A77: 31 | C77: 合計金額 | O77: 合計金額 | V77: totalAmount | AE77: - | AQ77: ラベル | AX77: 活性 | BO77: 数値 | CT77: 購入する商品の合計金額を表示
A78: 32 | C78: 確認画面へ進む | O78: 確認画面へ進む | V78: btnConfirm | AE78: - | AQ78: ボタン | AX78: 活性 | BO78: - | CT78: 注文内容確認画面へ遷移する

Sheet 画面設計書(カート商品画面)
A1: 画面設計書 | T1: システムID | X1: =表紙!AL45&"-0"&'画面設計書(カート商品画面)'!AW1 -> 20230711NHIH22000X001-016 | AH1: 改訂日 | AL1: 46206 | AU1: No. | AW1: 16
T2: システム名称 | X2: =表紙!AL3 -> 0 | AH2: 改訂者 | AL2: HAL太郎
A5: 画面設計書-画面名
A44: No | C44: 画面項目名 | O44: ラベル名 | V44: 項目ID | AE44: 取得テーブル | AN44: 上位 | AQ44: 種別 | AX44: 表示仕様 | BG44: 必須 | BO44: 型 | BS44: 桁 | BV44: 入力制限 | CC44: 入力制限備考 | CT44: 備考
A45: ↓header
A46: 1 | C46: 編集 | O46: +出品 | V46: Add Listing | AQ46: ボタン | AX46: 活性 | CT46: 出品内容編集画面へ遷移する
A47: 2 | C47: カート数 | O47: カート数 | V47: Carts | AQ47: ボタン | AX47: 活性 | CT47: カートの数を表示する
B48: 3 | C48: 戻る | O48: 戻る | V48: Return | AQ48: ボタン | AX48: 活性 | CT48: 前のページに戻る
A49: ↓main
A50: 4 | C50: 商品画像 | O50: 商品画像 | V50: ProductImage | AE50: t_images | AQ50: ファイル選択 | AX50: 活性 | BO50: 画像 | CT50: 商品の画像
A51: 5 | C51: 商品名 | O51: 商品名 | V51: ProductName | AE51: m_Product | AQ51: ラベル | AX51: 活性 | BO51: 文字列 | BS51: 50 | CT51: 商品の名前の表示
A52: 6 | C52: 価格 | O52: 価格 | V52: Price | AE52: m_Product | AQ52: ラベル | AX52: 活性 | BO52: 数値 | BS52: 5 | CT52: 価格の表示
A53: 7 | C53: 数量 | O53: 数量 | V53: Quantity | AE53: t_Cart | AQ53: ラベル | AX53: 活性 | BO53: 数値 | BU53: 5 | CT53: 数量の表示
A54: 8 | C54: 削除 | O54: 削除 | V54: Delete | AE54: - | AQ54: ボタン | AX54: 活性 | CT54: カートの商品の削除
A55: 9 | C55: 小計 | O55: 小計 | V55: Subtotal | AE55: t_cart | AQ55: ラベル | AX55: 活性 | BO55: 文字列 | BS55: 255 | CT55: 商品の合計金額の表示
A56: 10 | C56: 送料 | O56: 送料 | V56: Shipping fee | AE56: - | AQ56: ラベル | AX56: 活性 | BO56: 文字列 | BS56: 255 | CT56: 送料の表示
A57: 11 | C57: 合計 | O57: 合計 | V57: Total | AE57: - | AQ57: ラベル | AX57: 活性 | BO57: 文字列 | BS57: 255 | CT57: 商品と送料の合算の表示
A58: 12 | C58: 配送先 | O58: 配送先 | V58: Delivery address | AE58: m_member | AQ58: ラベル | AX58: 活性 | BO58: 文字列 | BS58: 255 | CT58: 配送先情報の表示
A59: 13 | C59: 変更 | O59: 変更 | V59: Change | AE59: - | AQ59: ボタン | AX59: 活性 | CT59: 配送先の住所を変更する画面に遷移する
A60: 14 | C60: レジに進む | O60: レジに進む | V60: register | AE60: - | AQ60: ボタン | AX60: 活性 | CT60: 購入手続き画面に遷移する

Sheet 画面設計書(ログイン画面)
A1: 画面設計書 | T1: システムID | X1: =表紙!AL45&"-0"&'画面設計書(ログイン画面)'!AW1 -> 20230711NHIH22000X001-016 | AH1: 改訂日 | AL1: 46206 | AU1: No. | AW1: 16
T2: システム名称 | X2: =表紙!AL3 -> 0 | AH2: 改訂者 | AL2: HAL太郎
A5: 画面設計書-画面名
A44: No | C44: 画面項目名 | O44: ラベル名 | V44: 項目ID | AE44: 取得テーブル | AN44: 上位 | AQ44: 種別 | AX44: 表示仕様 | BG44: 必須 | BO44: 型 | BS44: 桁 | BV44: 入力制限 | CC44: 入力制限備考 | CT44: 備考
A45: ↓main
A46: 1 | C46: メールアドレス入力 | O46: Email_address | V46: Email | AE46: - | AQ46: テキストエリア | AX46: 活性 | BO46: 文字列 | BS46: 20 | CT46: メールアドレスを入力する
A47: 2 | C47: パスワード入力 | O47: password | V47: password | AE47: - | AQ47: テキストエリア | AX47: 活性 | BO47: 文字列 | BS47: 20 | CT47: パスワードを入力する(最低8文字)
A48: 3 | C48: ログイン状態保持 | O48: Remember for 30 days | V48: Remenber | AE48: - | AQ48: チェックボックス | AX48: 活性 | CT48: 30日間ログイン状態を保持するためのチェックボックス
A49: 4 | C49: ログインボタン | O49: Login | V49: Login | AE49: - | AQ49: ボタン | AX49: 活性 | CT49: ボタンを押すとログイン完了
A50: 5 | C50: Google | O50: SIng in with Google | V50: Google | AE50: - | AQ50: ボタン | AX50: 活性 | CT50: Googleアカウントを利用する
A51: 6 | C51: Apple | O51: Sing in with Apple | V51: Apple | AE51: - | AQ51: ボタン | AX51: 活性 | CT51: Appleアカウントを利用する
A52: 7 | C52: 新規登録 | O52: Sing up | V52: Sing_up | AE52: - | AQ52: ボタン | AX52: 活性 | CT52: アカウントを持っていない場合新規登録画面に遷移する

Sheet 画面設計書(出品一覧)
A1: 画面設計書 | T1: システムID | X1: =表紙!AL45&"-0"&'画面設計書(出品一覧)'!AW1 -> 20230711NHIH22000X001-016 | AH1: 改訂日 | AL1: 46206 | AU1: No. | AW1: 16
T2: システム名称 | X2: =表紙!AL3 -> 0 | AH2: 改訂者 | AL2: HAL太郎
A5: 画面設計書-画面名
A44: No | C44: 画面項目名 | O44: ラベル名 | V44: 項目ID | AE44: 取得テーブル | AN44: 上位 | AQ44: 種別 | AX44: 表示仕様 | BG44: 必須 | BO44: 型 | BS44: 桁 | BV44: 入力制限 | CC44: 入力制限備考 | CT44: 備考
A45: ↓header
A46: 1 | C46: 追加出品ボタン | O46: +出品 | V46: Add Listing | AQ46: ボタン | AX46: 活性 | CT46: 出品内容編集画面へ遷移する
A47: 2 | C47: 戻るボタン | O47: 戻る | V47: Return | AQ47: ボタン | AX47: 活性 | CT47: 前のページに戻る
A48: ↓main
A49: 3 | C49: 販売中 | O49: 販売中 | V49: On_sale | AQ49: ボタン | AX49: 活性 | CT49: 販売中の出品を一覧表示する
A50: 4 | C50: 売却済み | O50: 売却済み | V50: Sold | AQ50: ボタン | AX50: 活性 | CT50: 売却済みの出品を一覧表示する
A51: 5 | C51: 下書き | O51: 下書き | V51: Draft | AQ51: ボタン | AX51: 活性 | CT51: 下書きの出品を一覧表示する
A52: 6 | C52: 商品画像 | O52: 商品画像 | V52: ProductImage | AE52: m_Image | AQ52: ラベル | AX52: 活性 | BO52: 画像 | CT52: 出品商品の画像を表示する
A53: 7 | C53: 商品名 | O53: 商品名 | V53: ProductName | AE53: m_Product | AQ53: ラベル | AX53: 活性 | BO53: 文字列 | BU53: 20 | CT53: 出品名を表示する
A54: 8 | C54: 価格 | O54: 価格 | V54: price | AE54: m_Product | AQ54: ラベル | AX54: 活性 | BO54: 数値 | BS54: 5 | CT54: 価格を表示する
A55: 9 | C55: 編集 | O55: 編集 | V55: Edit | AQ55: ボタン | AX55: 活性 | CT55: 出品内容編集画面へ遷移する
A56: 10 | C56: 取り下げ | O56: 取り下げ | V56: Withdrawal | AQ56: ボタン | AX56: 活性 | CT56: 出品取り下げ画面へ遷移する

Sheet 画面設計書(商品取り下げ)
A1: 画面設計書 | T1: システムID | X1: =表紙!AL45&"-0"&'画面設計書(商品取り下げ)'!AW1 -> 20230711NHIH22000X001-016 | AH1: 改訂日 | AL1: 46206 | AU1: No. | AW1: 16
T2: システム名称 | X2: =表紙!AL3 -> 0 | AH2: 改訂者 | AL2: HAL太郎
A5: 画面設計書-画面名
A44: No | C44: 画面項目名 | O44: ラベル名 | V44: 項目ID | AE44: 取得テーブル | AN44: 上位 | AQ44: 種別 | AX44: 表示仕様 | BG44: 必須 | BO44: 型 | BS44: 桁 | BV44: 入力制限 | CC44: 入力制限備考 | CT44: 備考
A45: ↓main
A46: 1 | C46: 取り下げ理由 | O46: 取り下げ理由の記入 | V46: Reason entry | AE46: m_Listing Status | AQ46: テキストエリア | AX46: 活性 | BO46: 文字列 | BS46: 225 | CT46: 商品を取り下げる理由を入力する
A47: 2 | C47: キャンセル | O47: キャンセル | V47: Cancel | AE47: - | AQ47: ボタン | AX47: 活性 | CT47: 取り下げをキャンセルする
A48: 3 | C48: 取り下げ | O48: 取り下げ | V48: Withdrawal | AE48: - | AQ48: ボタン | AX48: 活性 | CT48: 取り下げを行う

Sheet 画面設計書(会員情報)
A1: 画面設計書 | T1: システムID | X1: =表紙!AL45&"-0"&'画面設計書(会員情報)'!AW1 -> 20230711NHIH22000X001-016 | AH1: 改訂日 | AL1: 46206 | AU1: No. | AW1: 16
T2: システム名称 | X2: =表紙!AL3 -> 0 | AH2: 改訂者 | AL2: HAL太郎
A5: 画面設計書-画面名
BB10: 変更した方が良いところ
BB11: 商品説明を詳細にわける
A44: No | C44: 画面項目名 | O44: ラベル名 | V44: 項目ID | AE44: 取得テーブル | AN44: 上位 | AQ44: 種別 | AX44: 表示仕様 | BG44: 必須 | BO44: 型 | BS44: 桁 | BV44: 入力制限 | CC44: 入力制限備考 | CT44: 備考
A45: ↓header
A46: 1 | C46: 保存ボタン | O46: 保存 | V46: Save | AE46: ー | AQ46: ボタン | AX46: 活性 | CT46: 出品情報を更新する
A47: 2 | C47: 戻るボタン | O47: 戻る | V47: Return | AE47: ー | AQ47: ボタン | AX47: 活性 | CT47: 出品一覧画面へ遷移する
A48: ↓main
A49: 3 | C49: 名前 | O49: 名前 | V49: Name | AE49: m_member | AQ49: テキストエリア | AX49: 活性 | BO49: 文字型 | BS49: 20 | CT49: ユーザー名を登録する
A50: 4 | C50: メールアドレス | O50: メールアドレス | V50: Email | AE50: m_member | AQ50: テキストエリア | AX50: 活性 | BO50: 文字型 | BS50: 20 | CT50: メールアドレスを登録する
A51: 5 | C51: 電話番号 | O51: 電話番号 | V51: telmember | AE51: m_member | AQ51: テキストエリア | AX51: 活性 | BO51: 文字型 | BS51: 20 | CT51: パスワードを登録する(最低8文字)
A52: 6 | C52: 住所 | O52: 住所 | V52: Address | AE52: m_member | AQ52: テキストエリア | AX52: 活性 | BO52: 文字型 | BS52: 225 | CT52: 住所を登録する

Sheet 画面設計書(出品内容編集)
A1: 画面設計書 | T1: システムID | X1: =表紙!AL45&"-0"&'画面設計書(出品内容編集)'!AW1 -> 20230711NHIH22000X001-016 | AH1: 改訂日 | AL1: 46206 | AU1: No. | AW1: 16
T2: システム名称 | X2: =表紙!AL3 -> 0 | AH2: 改訂者 | AL2: HAL太郎
A5: 画面設計書-画面名
A44: No | C44: 画面項目名 | O44: ラベル名 | V44: 項目ID | AE44: 取得テーブル | AN44: 上位 | AQ44: 種別 | AX44: 表示仕様 | BG44: 必須 | BO44: 型 | BS44: 桁 | BV44: 入力制限 | CC44: 入力制限備考 | CT44: 備考
A45: ↓header
A46: 1 | C46: 保存ボタン | O46: 保存 | V46: Save | AE46: ー | AQ46: ボタン | AX46: 活性 | CT46: 出品情報を更新する
A47: 2 | C47: 戻るボタン | O47: 戻る | V47: Return | AE47: ー | AQ47: ボタン | AX47: 活性 | CT47: 出品一覧画面へ遷移する
A48: ↓main
A49: 1 | C49: 商品画像 | O49: 商品画像 | V49: ProductImage | AE49: t_images | AQ49: ファイル選択 | AX49: 活性 | BO49: 画像 | CT49: 出品商品の画像を表示する
A50: 2 | C50: 画像追加ボタン | O50: 画像追加 | V50: addImage | AQ50: ボタン | AX50: 活性 | BO50: - | CT50: 商品画像を追加する
A51: 3 | C51: 商品名 | O51: 商品名 | V51: ProductName | AE51: m_Product | AQ51: テキストエリア | AX51: 活性 | BO51: 文字列 | BS51: 20 | CT51: 出品名を入力する
A52: 4 | C52: カテゴリ選択 | O52: カテゴリ選択 | V52: CategorySelection | AE52: m_system | AQ52: コンボボックス | AX52: 活性 | BO52: 文字列 | BS52: 225 | CT52: カテゴリを選択する
A53: 5 | C53: 価格入力 | O53: 価格入力 | V53: enterPrice | AE53: - | AQ53: テキストエリア | AX53: 活性 | BO53: 数値 | BU53: 5 | CT53: 価格を入力する
A54: 6 | C54: サイズ選択 | O54: サイズ選択 | V54: SselectSize | AE54: m_size | AQ54: コンボボックス | AX54: 活性 | BO54: 文字列 | BS54: 5 | CT54: サイズを選択する
A55: 7 | C55: 状態記入欄 | O55: 状態記入 | V55: Condition | AE55: m_Product | AQ55: テキストエリア | AX55: 活性 | BO55: 文字列 | BS55: 225 | CT55: 商品の状態を記入する
A56: 8 | C56: 素材 | O56: 素材 | V56: material | AE56: m_Material | AQ56: チェックボックス | AX56: 活性 | BO56: 文字列 | BS56: 20 | CT56: 素材を選択する
A57: 9 | C57: 新品 | O57: 新品商品 | V57: new | AE57: m_Listing Status | AQ57: ラジオボタン | AX57: 活性 | BO57: 文字列 | BS57: 20 | CT57: 新品であるかを選択する
A58: 10 | C58: 中古 | O58: 中古 | V58: used | AE58: m_Listing Status | AQ58: ラジオボタン | AX58: 活性 | BO58: 文字列 | BS58: 20 | CT58: 中古であるかを選択する
A59: 11 | C59: 汚れや傷の有無 | O59: 汚れや傷の有無 | V59: conditionIssues | AE59: m_Listing Status | AQ59: チェックボックス | AX59: 非活性 | BO59: 文字列 | BS59: 20 | CT59: 傷や汚れの状態を選択する
A60: 12 | C60: その他(記入) | O60: その他 | V60: others | AE60: m_Listing Status | AQ60: テキストエリア | AX60: 非活性 | BO60: 文字列 | BS60: 225 | CT60: その他の状態を記入する
A61: 13 | C61: 更新 | O61: 更新 | V61: update | AE61: - | AQ61: ボタン | AX61: 活性 | BO61: - | CT61: 出品情報を更新する
A62: 14 | C62: 取り下げ | O62: 取り下げ | V62: withdraw | AE62: - | AQ62: ボタン | AX62: 活性 | BO62: - | CT62: 出品取り下げ画面へ遷移する

Sheet 画面設計書(新規登録画面)
A1: 画面設計書 | T1: システムID | X1: =表紙!AL45&"-0"&'画面設計書(新規登録画面)'!AW1 -> 20230711NHIH22000X001-016 | AH1: 改訂日 | AL1: 46206 | AU1: No. | AW1: 16
T2: システム名称 | X2: =表紙!AL3 -> 0 | AH2: 改訂者 | AL2: HAL太郎
A5: 画面設計書-画面名
A44: No | C44: 画面項目名 | O44: ラベル名 | V44: 項目ID | AE44: 取得テーブル | AN44: 上位 | AQ44: 種別 | AX44: 表示仕様 | BG44: 必須 | BO44: 型 | BS44: 桁 | BV44: 入力制限 | CC44: 入力制限備考 | CT44: 備考
A45: ↓main
A46: 1 | C46: 名前入力 | O46: Name | V46: Name | AE46: ー | AQ46: テキストエリア | AX46: 活性 | BO46: 文字列 | BS46: 20 | CT46: ユーザー名を登録する
A47: 2 | C47: メールアドレス入力 | O47: Email_address | V47: Email | AE47: ー | AQ47: テキストエリア | AX47: 活性 | BO47: 文字列 | BS47: 20 | CT47: メールアドレスを登録する
A48: 3 | C48: パスワード入力 | O48: password | V48: password | AE48: ー | AQ48: テキストエリア | AX48: 活性 | BO48: 文字列 | BS48: 20 | CT48: パスワードを登録する(最低8文字)
A49: 4 | C49: 新規登録ボタン | O49: Sing_up | V49: Sing_up | AE49: ー | AQ49: ボタン | AX49: 活性 | CT49: ボタンを押すと新規登録完了
A50: 5 | C50: Google | O50: SIng in with Google | V50: Google | AE50: ー | AQ50: ボタン | AX50: 活性 | CT50: Googleアカウントを利用する
A51: 6 | C51: Apple | O51: Sing in with Apple | V51: Apple | AE51: ー | AQ51: ボタン | AX51: 活性 | CT51: Appleアカウントを利用する
A52: 7 | C52: ログイン | O52: Login | V52: Login | AE52: ー | AQ52: ボタン | AX52: 活性 | CT52: アカウントを持っている場合ログイン画面に遷移する

Sheet 画面設計書(トップページ)
A1: 画面設計書 | T1: システムID | X1: =表紙!AL45&"-0"&'画面設計書(トップページ)'!AW1 -> 20230711NHIH22000X001-016 | AH1: 改訂日 | AL1: 46206 | AU1: No. | AW1: 16
T2: システム名称 | X2: =表紙!AL3 -> 0 | AH2: 改訂者 | AL2: HAL太郎
A5: 画面設計書-画面名
A44: No | C44: 画面項目名 | O44: ラベル名 | V44: 項目ID | AE44: 取得テーブル | AN44: 上位 | AQ44: 種別 | AX44: 表示仕様 | BG44: 必須 | BO44: 型 | BS44: 桁 | BV44: 入力制限 | CC44: 入力制限備考 | CT44: 備考
A45: ↓header
A46: 1 | C46: 画面切り替えボタン | O46: HandMade/Usedclothes | V46: Screen_switch | AE46: - | AQ46: コンボボックス | AX46: 活性 | BO46: 文字列 | BS46: 4 | CT46: ハンドメイド画面と古着画面を切り替える
A47: 2 | C47: 新商品おしらせ | O47: NewArrival | V47: NewProducts | AE47: - | AQ47: コンボボックス | AX47: 活性 | BO47: 文字列 | BS47: 5 | CT47: 新しい商品をお知らせとして表示する
A48: 3 | C48: セール商品 | O48: Sales | V48: sales_items | AE48: - | AQ48: ボタン | AX48: 活性 | CT48: セール商品を表示する
A49: 4 | C49: 性別 | O49: Men | V49: Men | AE49: m_member | AQ49: ボタン | AX49: 活性 | CT49: メンズ商品への切り替えボタン
B50: 5 | C50: 性別 | O50: Women | V50: Women | AE50: m_member | AQ50: ボタン | AX50: 活性 | CT50: レディース商品への切り替えボタン
A51: 6 | C51: エラーメッセージ | O51: エラーメッセージ | V51: txtMessage | AE51: - | AQ51: テキストエリア | AX51: 非活性 | BO51: 文字列 | BU51: 225 | CT51: エラーメッセージを表示する
A52: 7 | C52: 通知 | O52: 通知 | V52: Notification | AQ52: ボタン | AX52: 活性 | CT52: お知らせする項目を選択するボタン
A53: 8 | C53: カート | O53: カート | V53: Cart | AQ53: ボタン | AX53: 活性 | CT53: カートに入っている商品を表示するボタン
A54: 9 | C54: プロフィール | O54: 会員 | V54: Profile | AE54: m_member | AQ54: ボタン | AX54: 活性 | CT54: プロフィールを表示するボタン
A55: 10 | C55: 検索 | O55: 検索 | V55: searchBox | AE55: t_Searth | AQ55: テキストエリア | AX55: 活性 | BO55: 文字列 | BU55: 255 | CT55: 検索欄
A56: ↓main
A57: 11 | C57: 画像 | O57: images | V57: images | AE57: - | AQ57: ファイル選択 | AX57: 活性 | BO57: 画像 | CT57: 商品の画像を表示する
A58: 12 | C58: AIスタイリング | O58: Get styled | V58: Get_styled | AE58: - | AQ58: ボタン | AX58: 活性 | CT58: ファッションの知識がなくてもAIがスタイルを選んでくれるボタン
A59: 13 | C59: 商品一覧 | O59: 商品一覧 | V59: Product_List | AE59: m_Product | AQ59: 一覧 | AX59: 活性 | CT59: 商品を一覧で表示する
A60: 14 | C60: 商品画像 | O60: 商品画像 | V60: ProductImage | AE60: m_Image | AQ60: ファイル選択 | AX60: 活性 | BO60: 画像 | CT60: 商品の画像を表示する
A61: 15 | C61: 商品名 | O61: 商品名 | V61: ProductName | AE61: m_Product | AQ61: ラベル | AX61: 活性 | BO61: 文字列 | BS61: 20 | CT61: 出品名をで表示する
A62: 16 | C62: 価格 | O62: 価格 | V62: Price | AE62: m_Product | AQ62: ラベル | AX62: 活性 | BO62: 数値 | BS62: 5 | CT62: 価格を表示する
A63: 17 | C63: ブランド名 | O63: ブランド名 | V63: Brand | AE63: m_Product | AQ63: ラベル | AX63: 活性 | BO63: 文字列 | BS63: 20 | CT63: ブランドを表示する
A64: 18 | C64: 出品者名 | O64: 出品者名 | V64: Saler | AE64: m_Listing Status | AQ64: ラベル | AX64: 活性 | BO64: 文字列 | BS64: 20 | CT64: 出品者名を表示する
A65: 19 | C65: アクセサリー | O65: アクセサリー | V65: Accessories | AE65: m_Category | AQ65: ボタン | AX65: 活性 | CT65: アクセサリー一覧を表示する
A66: 20 | C66: バッグ | O66: バッグ | V66: Bag | AE66: m_Category | AQ66: ボタン | AX66: 活性 | CT66: バッグ一覧を表示する
A67: 21 | C67: 帽子 | O67: 帽子 | V67: Hat | AE67: m_Category | AQ67: ボタン | AX67: 活性 | CT67: 帽子一覧を表示する
A68: 22 | C68: アウター | O68: アウター | V68: Outerwear | AE68: m_Category | AQ68: ボタン | AX68: 活性 | CT68: アウター一覧を表示する
A69: 23 | C69: シューズ | O69: シューズ | V69: Shoes | AE69: m_Category | AQ69: ボタン | AX69: 活性 | CT69: 靴の一覧を表示する
A70: 24 | C70: 小物 | O70: 小物 | V70: Other | AE70: m_Category | AQ70: ボタン | AX70: 活性 | CT70: 小物一覧を表示する
A71: 25 | C71: カート | O71: カート | V71: Cart | AE71: m_Cart | AQ71: ボタン | AX71: 活性 | CT71: 商品をカートに追加するボタン
A72: 26 | C72: お気に入り | O72: お気に入り | V72: favorite | AE72: m_nice/Favorite/Follow | AQ72: アイコン | AX72: 活性 | CT72: お気に入りに登録できる機能
